Workbook

Sheet #SLH1
A21: Day | C21: Mon | D21: Tue | E21: Wed | F21: Thu | G21: Fri | H21: Sat | I21: Sun | J21: Mon | K21: Tue | L21: Wed | M21: Thu | N21: Fri | O21: Sat | P21: Sun | Q21: Mon | R21: Tue | S21: Wed | T21: Thu | U21: Fri | V21: Sat | W21: Sun | X21: Mon | Y21: Tue | Z21: Wed | AA21: Thu | AB21: Fri | AC21: Sat | AD21: Sun | AE21: Mon | AF21: Tue | AG21: Wed | AH21: Total No of Error | AI21: Percentage | AJ21: Remark : Top 3 Error Station
A22: Date | C22: 46143 | D22: 46144 | E22: 46145 | F22: 46146 | G22: 46147 | H22: 46148 | I22: 46149 | J22: 46150 | K22: 46151 | L22: 46152 | M22: 46153 | N22: 46154 | O22: 46155 | P22: 46156 | Q22: 46157 | R22: 46158 | S22: 46159 | T22: 46160 | U22: 46161 | V22: 46162 | W22: 46163 | X22: 46164 | Y22: 46165 | Z22: 46166 | AA22: 46167 | AB22: 46168 | AC22: 46169 | AD22: 46170 | AE22: 46171 | AF22: 46172 | AG22: 46173
A23: Total Unit | C23: =SUMIF($A40:$A336,C22,$B40:$B336) -> 1671 | D23: =SUMIF($A40:$A336,D22,$B40:$B336) -> 6329 | E23: =SUMIF($A40:$A336,E22,$B40:$B336) -> 4008 | F23: =SUMIF($A40:$A336,F22,$B40:$B336) -> 17417 | G23: =SUMIF($A40:$A336,G22,$B40:$B336) -> 687 | H23: =SUMIF($A40:$A336,H22,$B40:$B336) -> 0 | I23: =SUMIF($A40:$A336,I22,$B40:$B336) -> 0 | J23: =SUMIF($A40:$A336,J22,$B40:$B336) -> 15510 | ... AG23: =SUMIF($A40:$A336,AG22,$B40:$B336) -> 0 | AI23: =SUM(C23:AG23) -> 147846
A24: Jam count | C24: =SUM(C26:C36) -> 0 | D24: =SUM(D26:D36) -> 1 | E24: =SUM(E26:E36) -> 1 | F24: =SUM(F26:F36) -> 4 | G24: =SUM(G26:G36) -> 1 | H24: =SUM(H26:H36) -> 0 | I24: =SUM(I26:I36) -> 0 | J24: =SUM(J26:J36) -> 3 | ... AC24: =SUM(AC26:AC36) -> 1 | AD24: 0 | AE24: 0 | AF24: 0 | AG24: 0 | AH24: =SUBTOTAL(9,C24:AG24) -> 30 | AI24: TOTAL QTY JAM
A25: PPJ | C25: =IF(C24=0, C23, C23/C24) -> 1671 | D25: =IF(D24=0, D23, D23/D24) -> 6329 | E25: =IF(E24=0, E23, E23/E24) -> 4008 | F25: =IF(F24=0, F23, F23/F24) -> 4354.25 | G25: =IF(G24=0, G23, G23/G24) -> 687 | H25: =IF(H24=0, H23, H23/H24) -> 0 | I25: =IF(I24=0, I23, I23/I24) -> 0 | J25: =IF(J24=0, J23, J23/J24) -> 5170 | ... AG25: =IF(AG24=0, AG23, AG23/AG24) -> 0 | AI25: =AI23/AH37 -> 4928.2
A26: Stacker | C26: 0 | D26: 0 | E26: 1 | F26: 0 | G26: 0 | H26: 0 | I26: 0 | J26: 1 | K26: 0 | L26: 0 | M26: 0 | N26: 0 | O26: 0 | P26: 0 | Q26: 0 | R26: 0 | S26: 0 | T26: 0 | U26: 0 | V26: 0 | W26: 0 | X26: 0 | Y26: 0 | Z26: 1 | AA26: 0 | AB26: 0 | AC26: 0 | AD26: 0 | AE26: 0 | AF26: 0 | AG26: 0 | AH26: =SUBTOTAL(9,C26:AG26) -> 3 | AI26: =AH26/AH24 -> 0.1
A27: Transfer | C27: 0 | D27: 0 | E27: 0 | F27: 0 | G27: 0 | H27: 0 | I27: 0 | J27: 0 | K27: 0 | L27: 0 | M27: 1 | N27: 1 | O27: 0 | P27: 0 | Q27: 0 | R27: 0 | S27: 0 | T27: 1 | U27: 2 | V27: 0 | W27: 0 | X27: 0 | Y27: 0 | Z27: 0 | AA27: 0 | AB27: 0 | AC27: 1 | AD27: 0 | AE27: 0 | AF27: 0 | AG27: 0 | AH27: =SUBTOTAL(9,C27:AG27) -> 6 | AI27: =AH27/AH24 -> 0.2
A28: Set Plate&BUFFER | C28: 0 | D28: 0 | E28: 0 | F28: 3 | G28: 1 | H28: 0 | I28: 0 | J28: 1 | K28: 0 | L28: 0 | M28: 0 | N28: 1 | O28: 1 | P28: 0 | Q28: 0 | R28: 0 | S28: 1 | T28: 1 | U28: 0 | V28: 0 | W28: 3 | X28: 0 | Y28: 0 | Z28: 0 | AA28: 0 | AB28: 0 | AC28: 0 | AD28: 0 | AE28: 0 | AF28: 0 | AG28: 0 | AH28: =SUBTOTAL(9,C28:AG28) -> 12 | AI28: =AH28/AH24 -> 0.4 | AL28: 0 | AM28: 0 | AN28: 0
A29: LD Flow&Middle | C29: 0 | D29: 0 | E29: 0 | F29: 0 | G29: 0 | H29: 0 | I29: 0 | J29: 0 | K29: 0 | L29: 0 | M29: 0 | N29: 0 | O29: 0 | P29: 0 | Q29: 0 | R29: 0 | S29: 0 | T29: 0 | U29: 0 | V29: 0 | W29: 0 | X29: 0 | Y29: 0 | Z29: 0 | AA29: 0 | AB29: 0 | AC29: 0 | AD29: 0 | AE29: 0 | AF29: 0 | AG29: 0 | AH29: =SUBTOTAL(9,C29:AF29) -> 0 | AI29: =AH29/AH24 -> 0
A30: UD Flow&Middle | C30: 0 | D30: 0 | E30: 0 | F30: 0 | G30: 0 | H30: 0 | I30: 0 | J30: 0 | K30: 0 | L30: 0 | M30: 0 | N30: 0 | O30: 0 | P30: 0 | Q30: 0 | R30: 0 | S30: 0 | T30: 0 | U30: 0 | V30: 0 | W30: 0 | X30: 0 | Y30: 0 | Z30: 0 | AA30: 0 | AB30: 0 | AC30: 0 | AD30: 0 | AE30: 0 | AF30: 0 | AG30: 0 | AH30: =SUBTOTAL(9,C30:AG30) -> 0 | AI30: =AH30/AH24 -> 0
A31: INPUT FLOW | C31: 0 | D31: 0 | E31: 0 | F31: 0 | G31: 0 | H31: 0 | I31: 0 | J31: 0 | K31: 0 | L31: 0 | M31: 0 | N31: 0 | O31: 0 | P31: 0 | Q31: 0 | R31: 0 | S31: 0 | T31: 0 | U31: 0 | V31: 0 | W31: 0 | X31: 0 | Y31: 0 | Z31: 0 | AA31: 0 | AB31: 0 | AC31: 0 | AD31: 0 | AE31: 0 | AF31: 0 | AG31: 0 | AH31: =SUBTOTAL(9,C31:AG31) -> 0 | AI31: =AH31/AH24 -> 0
A32: OUTPUT FLOW | C32: 0 | D32: 0 | E32: 0 | F32: 0 | G32: 0 | H32: 0 | I32: 0 | J32: 0 | K32: 0 | L32: 0 | M32: 0 | N32: 0 | O32: 0 | P32: 0 | Q32: 0 | R32: 0 | S32: 0 | T32: 0 | U32: 0 | V32: 0 | W32: 0 | X32: 0 | Y32: 0 | Z32: 0 | AA32: 0 | AB32: 0 | AC32: 0 | AD32: 0 | AE32: 0 | AF32: 0 | AG32: 0 | AH32: =SUBTOTAL(9,C32:AG32) -> 0 | AI32: =AH32/AH24 -> 0
A33: Load Hand | C33: 0 | D33: 1 | E33: 0 | F33: 0 | G33: 0 | H33: 0 | I33: 0 | J33: 1 | K33: 0 | L33: 0 | M33: 0 | N33: 1 | O33: 0 | P33: 0 | Q33: 0 | R33: 0 | S33: 0 | T33: 0 | U33: 0 | V33: 0 | W33: 0 | X33: 0 | Y33: 0 | Z33: 1 | AA33: 0 | AB33: 0 | AC33: 0 | AD33: 0 | AE33: 0 | AF33: 0 | AG33: 0 | AH33: =SUBTOTAL(9,C33:AG33) -> 4 | AI33: =AH33/AH24 -> 0.13333333
A34: Unload Hand | C34: 0 | D34: 0 | E34: 0 | F34: 1 | G34: 0 | H34: 0 | I34: 0 | J34: 0 | K34: 0 | L34: 0 | M34: 0 | N34: 0 | O34: 0 | P34: 0 | Q34: 0 | R34: 0 | S34: 0 | T34: 0 | U34: 0 | V34: 0 | W34: 0 | X34: 0 | Y34: 0 | Z34: 1 | AA34: 1 | AB34: 0 | AC34: 0 | AD34: 0 | AE34: 0 | AF34: 0 | AG34: 0 | AH34: =SUBTOTAL(9,C34:AG34) -> 3 | AI34: =AH34/AH24 -> 0.1
A35: TEST SITE | C35: 0 | D35: 0 | E35: 0 | F35: 0 | G35: 0 | H35: 0 | I35: 0 | J35: 0 | K35: 0 | L35: 0 | M35: 0 | N35: 0 | O35: 0 | P35: 0 | Q35: 0 | R35: 0 | S35: 0 | T35: 2 | U35: 0 | V35: 0 | W35: 0 | X35: 0 | Y35: 0 | Z35: 0 | AA35: 0 | AB35: 0 | AC35: 0 | AD35: 0 | AE35: 0 | AF35: 0 | AG35: 0 | AH35: =SUBTOTAL(9,C35:AG35) -> 2 | AI35: =AH35/AH24 -> 0.066666667
A36: MOTOR | C36: 0 | D36: 0 | E36: 0 | F36: 0 | G36: 0 | H36: 0 | I36: 0 | J36: 0 | K36: 0 | L36: 0 | M36: 0 | N36: 0 | O36: 0 | P36: 0 | Q36: 0 | R36: 0 | S36: 0 | T36: 0 | U36: 0 | V36: 0 | W36: 0 | X36: 0 | Y36: 0 | Z36: 0 | AA36: 0 | AB36: 0 | AC36: 0 | AD36: 0 | AE36: 0 | AF36: 0 | AG36: 0 | AH36: =SUBTOTAL(9,C36:AG36) -> 0 | AI36: =AH36/AH24 -> 0
A37: Total | C37: =SUM(C26:C36) -> 0 | D37: =SUM(D26:D36) -> 1 | E37: =SUM(E26:E36) -> 1 | F37: =SUM(F26:F36) -> 4 | G37: =SUM(G26:G36) -> 1 | H37: =SUM(H26:H36) -> 0 | I37: =SUM(I26:I36) -> 0 | J37: =SUM(J26:J36) -> 3 | ... AG37: =SUM(AG26:AG36) -> 0 | AH37: =SUBTOTAL(9,C37:AG37) -> 30 | AI37: TOTAL QTY JAM
A39: Total | B39: =SUM(B41:B425) -> 147846 | C39: T/Jam | D39: =AH37 -> 30 | E39: PPJ | F39: =AI25 -> 4928.2 | G39: BIN 4 | H39: =#REF! -> #REF!
A40: Date | B40: Total Unit | C40: No Jam | D40: Error code | F40: Error Massage | O40: Finding/Action | W40: Err. Time | X40: Err. Point
F42: =IFERROR(VLOOKUP(D42,ErrorList!$A$1:$C$2305,3,FALSE),"-") -> - | X42: =IFERROR(VLOOKUP(D42,ErrorList!$A$1:$C$2305,2,FALSE),"-") -> -
F43: =IFERROR(VLOOKUP(D43,ErrorList!$A$1:$C$2305,3,FALSE),"-") -> - | X43: =IFERROR(VLOOKUP(D43,ErrorList!$A$1:$C$2305,2,FALSE),"-") -> -
F44: =IFERROR(VLOOKUP(D44,ErrorList!$A$1:$C$2305,3,FALSE),"-") -> - | X44: =IFERROR(VLOOKUP(D44,ErrorList!$A$1:$C$2305,2,FALSE),"-") -> -
F45: =IFERROR(VLOOKUP(D45,ErrorList!$A$1:$C$2305,3,FALSE),"-") -> - | X45: =IFERROR(VLOOKUP(D45,ErrorList!$A$1:$C$2305,2,FALSE),"-") -> -
F46: =IFERROR(VLOOKUP(D46,ErrorList!$A$1:$C$2305,3,FALSE),"-") -> - | X46: =IFERROR(VLOOKUP(D46,ErrorList!$A$1:$C$2305,2,FALSE),"-") -> -
A47: 46118 | F47: =IFERROR(VLOOKUP(D47,ErrorList!$A$1:$C$2305,3,FALSE),"-") -> - | X47: =IFERROR(VLOOKUP(D47,ErrorList!$A$1:$C$2305,2,FALSE),"-") -> -
F48: =IFERROR(VLOOKUP(D48,ErrorList!$A$1:$C$2305,3,FALSE),"-") -> -
F49: =IFERROR(VLOOKUP(D49,ErrorList!$A$1:$C$2305,3,FALSE),"-") -> -
F50: =IFERROR(VLOOKUP(D50,ErrorList!$A$1:$C$2305,3,FALSE),"-") -> -
F51: =IFERROR(VLOOKUP(D51,ErrorList!$A$1:$C$2305,3,FALSE),"-") -> -
F52: =IFERROR(VLOOKUP(D52,ErrorList!$A$1:$C$2305,3,FALSE),"-") -> -
F53: =IFERROR(VLOOKUP(D53,ErrorList!$A$1:$C$2305,3,FALSE),"-") -> -
F54: =IFERROR(VLOOKUP(D54,ErrorList!$A$1:$C$2305,3,FALSE),"-") -> -
A55: 46173 | B55: 0 | F55: =IFERROR(VLOOKUP(D55,ErrorList!$A$1:$C$2305,3,FALSE),"-") -> -
A56: 46172 | B56: 0 | F56: =IFERROR(VLOOKUP(D56,ErrorList!$A$1:$C$2305,3,FALSE),"-") -> -
A57: 46171 | B57: 2475 | F57: =IFERROR(VLOOKUP(D57,ErrorList!$A$1:$C$2305,3,FALSE),"-") -> -
A58: 46170 | B58: 180 | F58: =IFERROR(VLOOKUP(D58,ErrorList!$A$1:$C$2305,3,FALSE),"-") -> -
A59: 46169 | B59: 11999 | D59: 18002 | E59: 1 | F59: =IFERROR(VLOOKUP(D59,ErrorList!$A$1:$C$2305,3,FALSE),"-") -> Load Transfer C-Tray 방향 체크에 실패 하였습니다. | O59: 작업자 Human Err.로 인한 발생으로, C-tray 재투입 후 미발생. | W59: 0.69791667 | X59: =IFERROR(VLOOKUP(D59,ErrorList!$A$1:$C$2305,2,FALSE),"-") -> [TRANSFER]
A60: 46168 | B60: 0 | F60: =IFERROR(VLOOKUP(D60,ErrorList!$A$1:$C$2305,3,FALSE),"-") -> -
A61: 46167 | B61: 9993 | D61: 34085 | E61: 1 | F61: =IFERROR(VLOOKUP(D61,ErrorList!$A$1:$C$2305,3,FALSE),"-") -> Unloader Picker Module Clamp Cylinder #7 Sol 동작이 실패 하였습니다. | O61: 3번 tray 12번 insert 확인 결과 이상없음 재현시에도 특이사항 없어 단발성 error로 판단 되며 재발생 시 점검 예정 | W61: 0.014583333 | X61: =IFERROR(VLOOKUP(D61,ErrorList!$A$1:$C$2305,2,FALSE),"-") -> [UNLOAD_HAND]
A62: 46166 | B62: 12156 | D62: 25061 | E62: 1 | F62: =IFERROR(VLOOKUP(D62,ErrorList!$A$1:$C$2305,3,FALSE),"-") -> Load Picker Module Unclamp Cylinder #7 Sol 동작이 실패 하였습니다. | O62: T-tray front1 내려놓을 때 발생 발생당시 근무자 인터뷰 결과 insert 안착 불량으로 x값 teaching 진행 | W62: 0.58888889 | X62: =IFERROR(VLOOKUP(D62,ErrorList!$A$1:$C$2305,2,FALSE),"-") -> [LOAD_HAND]
...

Sheet ErrorList
A1: 32 | B1: [STACKER] | C1: Loader#1 VALID 센서가 감지되었습니다.
A2: 33 | B2: [STACKER] | C2: Loader#1 PIO CS_0 센서가 감지되었습니다.
A3: 34 | B3: [STACKER] | C3: Loader#1 PIO CS_1 센서가 감지되었습니다.
A4: 35 | B4: [STACKER] | C4: Loader#1 PIO CS_2 센서가 감지되었습니다.
A5: 36 | B5: [STACKER] | C5: Loader#1 PIO CS_3 센서가 감지되었습니다.
A6: 37 | B6: [STACKER] | C6: Loader#1 PIO TR_REQ 센서가 감지되었습니다.
A7: 38 | B7: [STACKER] | C7: Loader#1 PIO BUSY 센서가 감지되었습니다.
A8: 39 | B8: [STACKER] | C8: Loader#1 PIO COMPLETE 센서가 감지되었습니다.
A9: 40 | B9: [STACKER] | C9: Loader#2 VALID 센서가 감지되었습니다.
A10: 41 | B10: [STACKER] | C10: Loader#2 PIO CS_0 센서가 감지되었습니다.
A11: 42 | B11: [STACKER] | C11: Loader#2 PIO CS_1 센서가 감지되었습니다.
A12: 43 | B12: [STACKER] | C12: Loader#2 PIO CS_2 센서가 감지되었습니다.
... A2305: 118030 | B2305: [ETC] | C2305: Ionizer Flow Meter 값이 기준치 이하입니다.
